<?xml version="1.0"?>
<robot name="arm_robot" xmlns:xacro="http://www.ros.org/wiki/xacro">

  <!-- Properties -->
  <xacro:property name="density" value="2700"/>  <!-- Density in kg/m^3 -->

  <!-- Macro for calculating inertia for a box -->
  <xacro:macro name="inertia_box" params="mass x y z">
    <inertial>
      <mass value="${mass}"/>
      <origin rpy="0 0 0" xyz="0 0 0"/>
      <inertia 
        ixx="${mass * (y*y + z*z) / 12.0}"
        iyy="${mass * (x*x + z*z) / 12.0}"
        izz="${mass * (x*x + y*y) / 12.0}"
        ixy="0.0"
        ixz="0.0"
        iyz="0.0" />
    </inertial>
  </xacro:macro>

  <!-- Macro for calculating inertia for a cylinder -->
  <xacro:macro name="inertia_cylinder" params="mass radius length">
    <inertial>
      <mass value="${mass}"/>
      <origin rpy="0 0 0" xyz="0 0 0"/>
      <inertia 
        ixx="${mass * (3*radius*radius + length*length) / 12.0}"
        iyy="${mass * (3*radius*radius + length*length) / 12.0}"
        izz="${mass * radius*radius / 2.0}"
        ixy="0.0"
        ixz="0.0"
        iyz="0.0" />
    </inertial>
  </xacro:macro>

  <!-- Base Link -->
  <link name="base_link">
    <visual>
      <origin rpy="0 0 0" xyz="0 0 0"/>
      <geometry>
        <box size="0.2 1 0.1"/>
      </geometry>
    </visual>

    <collision>
      <origin rpy="0 0 0" xyz="0 0 0"/>
      <geometry>
        <box size="0.2 1 0.1"/>
      </geometry>
    </collision>
    <xacro:inertia_box mass="${density * 0.2 * 1 * 0.1}" x="0.2" y="1" z="0.1"/>
  </link>

  <!-- Prismatic Joint -->
  <joint name="arm1_p_joint" type="prismatic">
    <parent link="base_link"/>
    <child link="arm1_p_link"/>
    <origin rpy="0 0 0" xyz="0 0 0.1"/>
    <axis xyz="0 1 0"/>
    <limit lower="-0.4" upper="0.4" effort="50" velocity="0.2"/>
  </joint>

  <!-- First Prismatic Link -->
  <link name="arm1_p_link">
    <visual>
      <origin rpy="0 0 0" xyz="0 0 0"/>
      <geometry>
        <cylinder radius="0.1" length="0.1"/>
      </geometry>
    </visual>

    <collision>
      <origin rpy="0 0 0" xyz="0 0 0"/>
      <geometry>
        <cylinder radius="0.1" length="0.1"/>
      </geometry>
    </collision>
    <xacro:inertia_cylinder mass="${density * 3.14 * 0.1 * 0.1 * 0.1}" radius="0.1" length="0.1"/>
  </link>

  <!-- Revolute Joint -->
  <joint name="arm1_r_joint" type="revolute">
    <parent link="arm1_p_link"/>
    <child link="arm1_r_link"/>
    <origin rpy="0 0 0" xyz="0 0 0.1"/>
    <axis xyz="0 0 1"/>
    <limit lower="-3.14" upper="3.14" effort="50" velocity="1.0"/>
  </joint>

  <!-- First Revolute Link -->
  <link name="arm1_r_link">
    <visual>
      <origin rpy="0 0 0" xyz="0 0 0"/>
      <geometry>
        <cylinder radius="0.1" length="0.1"/>
      </geometry>
    </visual>
    <collision>
      <origin rpy="0 0 0" xyz="0 0 0"/>
      <geometry>
        <cylinder radius="0.1" length="0.1"/>
      </geometry>
    </collision>
    <xacro:inertia_cylinder mass="${density * 3.14 * 0.1 * 0.1 * 0.1}" radius="0.1" length="0.1"/>
  </link>

  <!-- Revolute Joint -->
  <joint name="arm2_joint" type="revolute">
    <parent link="arm1_r_link"/>
    <child link="arm2_link"/>
    <origin rpy="0 0 0" xyz="0 -0.2 0"/>
    <axis xyz="0 1 0"/>
    <limit lower="-3.14" upper="3.14" effort="50" velocity="1.0"/>
  </joint>

  <!-- Second Link -->
  <link name="arm2_link">
    <visual>
      <origin rpy="0 0 0" xyz="0 0 0"/>
      <geometry>
        <box size="0.2 0.2 0.1"/>
      </geometry>
    </visual>

    <visual>
      <origin rpy="0 0 0" xyz="0 0 0.3"/>
      <geometry>
        <cylinder radius="0.1" length="0.5"/>
      </geometry>
    </visual>

    <visual>
      <origin rpy="0 0 0" xyz="0 0 0.6"/>
      <geometry>
        <box size="0.2 0.2 0.1"/>
      </geometry>
    </visual>

    <collision>
      <origin rpy="0 0 0" xyz="0 0 0"/>
      <geometry>
        <box size="0.2 0.2 0.1"/>
      </geometry>
    </collision>

    <collision>
      <origin rpy="0 0 0" xyz="0 0 0.3"/>
      <geometry>
        <cylinder radius="0.1" length="0.5"/>
      </geometry>
    </collision>

    <collision>
      <origin rpy="0 0 0" xyz="0 0 0.6"/>
      <geometry>
        <box size="0.2 0.2 0.1"/>
      </geometry>
    </collision>

    <xacro:inertia_box mass="${density * 0.2 * 0.2 * 0.1}" x="0.2" y="0.2" z="0.1"/>
  </link>

  <!-- Revolute Joint -->
  <joint name="arm3_joint" type="revolute">
    <parent link="arm2_link"/>
    <child link="arm3_link"/>
    <origin rpy="0 0 0" xyz="0 0.2 0.6"/>
    <axis xyz="0 1 0"/>
    <limit lower="-3.14" upper="3.14" effort="50" velocity="1.0"/>
  </joint>

  <!-- Third Link -->
  <link name="arm3_link">
    <visual>
      <origin rpy="0 0 0" xyz="0 0 0"/>
      <geometry>
        <box size="0.2 0.2 0.1"/>
      </geometry>
    </visual>

    <visual>
      <origin rpy="0 0 0" xyz="0 0 0.3"/>
      <geometry>
        <cylinder radius="0.1" length="0.5"/>
      </geometry>
    </visual>

    <collision>
      <origin rpy="0 0 0" xyz="0 0 0"/>
      <geometry>
        <box size="0.2 0.2 0.1"/>
      </geometry>
    </collision>

    <collision>
      <origin rpy="0 0 0" xyz="0 0 0.3"/>
      <geometry>
        <cylinder radius="0.1" length="0.5"/>
      </geometry>
    </collision>
    <xacro:inertia_box mass="${density * 0.2 * 0.2 * 0.1}" x="0.2" y="0.2" z="0.1"/>
  </link>

  <!-- Prismatic Joint -->
  <joint name="arm4_joint" type="prismatic">
    <parent link="arm3_link"/>
    <child link="arm4_link"/>
    <origin rpy="0 0 0" xyz="0 0 0.3"/>
    <axis xyz="0 0 1"/>
    <limit lower="0" upper="0.5" effort="50" velocity="0.2"/>
  </joint>

  <!-- Fourth Link -->
  <link name="arm4_link">
    <visual>
      <origin rpy="0 0 0" xyz="0 0 0"/>
      <geometry>
        <cylinder radius="0.08" length="0.5"/>
      </geometry>
    </visual>

    <visual>
      <origin rpy="0 0 0" xyz="0 0 0.3"/>
      <geometry>
        <cylinder length="0.1" radius="0.1" />
      </geometry>
    </visual> 

    <collision>
      <origin rpy="0 0 0" xyz="0 0 0"/>
      <geometry>
        <cylinder radius="0.08" length="0.5"/>
      </geometry>
    </collision>

    <collision>
      <origin rpy="0 0 0" xyz="0 0 0.3"/>
      <geometry>
        <cylinder length="0.1" radius="0.1" />
      </geometry>
    </collision>
    
    <xacro:inertia_cylinder mass="${density * 3.14 * 0.08 * 0.08 * 0.5}" radius="0.08" length="0.5"/>
  </link>

  <!-- Fixed Joint for Tool -->
  <joint name="tool_joint" type="fixed">
    <parent link="arm4_link"/>
    <child link="tool_link"/>
    <origin rpy="0 0 0" xyz="0 0 0.3"/>
  </joint>

  <link name="tool_link"/>

  <!-- Transmissions -->
  <transmission name="trans_arm1_p_joint">
    <type>transmission_interface/SimpleTransmission</type>
    <joint name="arm1_p_joint">
      <hardwareInterface>hardware_interface/EffortJointInterface</hardwareInterface>
    </joint>
    <actuator name="actuator_arm1_p">
      <mechanicalReduction>1</mechanicalReduction>
    </actuator>
  </transmission>

  <transmission name="trans_arm1_r_joint">
    <type>transmission_interface/SimpleTransmission</type>
    <joint name="arm1_r_joint">
      <hardwareInterface>hardware_interface/EffortJointInterface</hardwareInterface>
    </joint>
    <actuator name="actuator_arm1_r">
      <mechanicalReduction>1</mechanicalReduction>
    </actuator>
  </transmission>

  <transmission name="trans_arm2_joint">
    <type>transmission_interface/SimpleTransmission</type>
    <joint name="arm2_joint">
      <hardwareInterface>hardware_interface/EffortJointInterface</hardwareInterface>
    </joint>
    <actuator name="actuator_arm2">
      <mechanicalReduction>1</mechanicalReduction>
    </actuator>
  </transmission>

  <transmission name="trans_arm3_joint">
    <type>transmission_interface/SimpleTransmission</type>
    <joint name="arm3_joint">
      <hardwareInterface>hardware_interface/EffortJointInterface</hardwareInterface>
    </joint>
    <actuator name="actuator_arm3">
      <mechanicalReduction>1</mechanicalReduction>
    </actuator>
  </transmission>

  <transmission name="trans_arm4_joint">
    <type>transmission_interface/SimpleTransmission</type>
    <joint name="arm4_joint">
      <hardwareInterface>hardware_interface/EffortJointInterface</hardwareInterface>
    </joint>
    <actuator name="actuator_arm4">
      <mechanicalReduction>1</mechanicalReduction>
    </actuator>
  </transmission>

</robot>